[2024-05-18T01:47:30.787+0530] {taskinstance.py:1103} INFO - Dependencies all met for dep_context=non-requeueable deps ti=<TaskInstance: iris_classification.preprocess_data manual__2024-05-17T20:17:25.611478+00:00 [queued]>
[2024-05-18T01:47:30.790+0530] {taskinstance.py:1103} INFO - Dependencies all met for dep_context=requeueable deps ti=<TaskInstance: iris_classification.preprocess_data manual__2024-05-17T20:17:25.611478+00:00 [queued]>
[2024-05-18T01:47:30.790+0530] {taskinstance.py:1308} INFO - Starting attempt 1 of 0
[2024-05-18T01:47:30.795+0530] {taskinstance.py:1327} INFO - Executing <Task(PythonOperator): preprocess_data> on 2024-05-17 20:17:25.611478+00:00
[2024-05-18T01:47:30.799+0530] {standard_task_runner.py:57} INFO - Started process 10120 to run task
[2024-05-18T01:47:30.800+0530] {clientserver.py:543} INFO - Closing down clientserver connection
[2024-05-18T01:47:30.803+0530] {standard_task_runner.py:84} INFO - Running: ['airflow', 'tasks', 'run', 'iris_classification', 'preprocess_data', 'manual__2024-05-17T20:17:25.611478+00:00', '--job-id', '43', '--raw', '--subdir', 'DAGS_FOLDER/main.py', '--cfg-path', '/var/folders/fy/4q0txy357vvc35bhsxlfyr8c0000gn/T/tmpfnx0ho50']
[2024-05-18T01:47:30.804+0530] {standard_task_runner.py:85} INFO - Job 43: Subtask preprocess_data
[2024-05-18T01:47:30.824+0530] {task_command.py:410} INFO - Running <TaskInstance: iris_classification.preprocess_data manual__2024-05-17T20:17:25.611478+00:00 [running]> on host aswins-macbook-air.local
[2024-05-18T01:47:30.854+0530] {taskinstance.py:1545} INFO - Exporting env vars: AIRFLOW_CTX_DAG_OWNER='airflow' AIRFLOW_CTX_DAG_ID='iris_classification' AIRFLOW_CTX_TASK_ID='preprocess_data' AIRFLOW_CTX_EXECUTION_DATE='2024-05-17T20:17:25.611478+00:00' AIRFLOW_CTX_TRY_NUMBER='1' AIRFLOW_CTX_DAG_RUN_ID='manual__2024-05-17T20:17:25.611478+00:00'
[2024-05-18T01:47:31.518+0530] {taskinstance.py:1824} ERROR - Task failed with exception
Traceback (most recent call last):
  File "/Users/aswin/anaconda3/envs/bdl/lib/python3.10/site-packages/airflow/operators/python.py", line 181, in execute
    return_value = self.execute_callable()
  File "/Users/aswin/anaconda3/envs/bdl/lib/python3.10/site-packages/airflow/operators/python.py", line 198, in execute_callable
    return self.python_callable(*self.op_args, **self.op_kwargs)
  File "/Users/aswin/Downloads/Courses/Big Data Lab/Project/dags/main.py", line 55, in preprocess_data
    iris_data = spark.read.csv(iris_data_path, header=False, inferSchema=True)
  File "/Users/aswin/anaconda3/envs/bdl/lib/python3.10/site-packages/pyspark/sql/readwriter.py", line 740, in csv
    return self._df(self._jreader.csv(self._spark._sc._jvm.PythonUtils.toSeq(path)))
  File "/Users/aswin/anaconda3/envs/bdl/lib/python3.10/site-packages/py4j/java_gateway.py", line 1322, in __call__
    return_value = get_return_value(
  File "/Users/aswin/anaconda3/envs/bdl/lib/python3.10/site-packages/pyspark/errors/exceptions/captured.py", line 185, in deco
    raise converted from None
pyspark.errors.exceptions.captured.AnalysisException: [PATH_NOT_FOUND] Path does not exist: file:/Users/aswin/data/iris.csv.
[2024-05-18T01:47:31.529+0530] {taskinstance.py:1345} INFO - Marking task as FAILED. dag_id=iris_classification, task_id=preprocess_data, execution_date=20240517T201725, start_date=20240517T201730, end_date=20240517T201731
[2024-05-18T01:47:31.534+0530] {standard_task_runner.py:104} ERROR - Failed to execute job 43 for task preprocess_data ([PATH_NOT_FOUND] Path does not exist: file:/Users/aswin/data/iris.csv.; 10120)
[2024-05-18T01:47:31.578+0530] {local_task_job_runner.py:225} INFO - Task exited with return code 1
[2024-05-18T01:47:31.586+0530] {taskinstance.py:2651} INFO - 0 downstream tasks scheduled from follow-on schedule check
