[2024-05-17T16:20:51.491+0530] {taskinstance.py:1103} INFO - Dependencies all met for dep_context=non-requeueable deps ti=<TaskInstance: iris_classification.train_model manual__2024-05-17T10:45:29.500408+00:00 [queued]>
[2024-05-17T16:20:51.494+0530] {taskinstance.py:1103} INFO - Dependencies all met for dep_context=requeueable deps ti=<TaskInstance: iris_classification.train_model manual__2024-05-17T10:45:29.500408+00:00 [queued]>
[2024-05-17T16:20:51.494+0530] {taskinstance.py:1308} INFO - Starting attempt 2 of 2
[2024-05-17T16:20:51.499+0530] {taskinstance.py:1327} INFO - Executing <Task(PythonOperator): train_model> on 2024-05-17 10:45:29.500408+00:00
[2024-05-17T16:20:51.502+0530] {standard_task_runner.py:57} INFO - Started process 33774 to run task
[2024-05-17T16:20:51.503+0530] {clientserver.py:543} INFO - Closing down clientserver connection
[2024-05-17T16:20:51.506+0530] {standard_task_runner.py:84} INFO - Running: ['airflow', 'tasks', 'run', 'iris_classification', 'train_model', 'manual__2024-05-17T10:45:29.500408+00:00', '--job-id', '13', '--raw', '--subdir', 'DAGS_FOLDER/iris_prediction.py', '--cfg-path', '/var/folders/fy/4q0txy357vvc35bhsxlfyr8c0000gn/T/tmpqmwpy231']
[2024-05-17T16:20:51.507+0530] {standard_task_runner.py:85} INFO - Job 13: Subtask train_model
[2024-05-17T16:20:51.539+0530] {task_command.py:410} INFO - Running <TaskInstance: iris_classification.train_model manual__2024-05-17T10:45:29.500408+00:00 [running]> on host aswins-macbook-air.local
[2024-05-17T16:20:51.561+0530] {taskinstance.py:1545} INFO - Exporting env vars: AIRFLOW_CTX_DAG_OWNER='airflow' AIRFLOW_CTX_DAG_ID='iris_classification' AIRFLOW_CTX_TASK_ID='train_model' AIRFLOW_CTX_EXECUTION_DATE='2024-05-17T10:45:29.500408+00:00' AIRFLOW_CTX_TRY_NUMBER='2' AIRFLOW_CTX_DAG_RUN_ID='manual__2024-05-17T10:45:29.500408+00:00'
[2024-05-17T16:20:51.681+0530] {clientserver.py:505} INFO - Error while sending or receiving.
Traceback (most recent call last):
  File "/Users/aswin/anaconda3/envs/bdl/lib/python3.10/site-packages/py4j/clientserver.py", line 503, in send_command
    self.socket.sendall(command.encode("utf-8"))
BrokenPipeError: [Errno 32] Broken pipe
[2024-05-17T16:20:51.683+0530] {clientserver.py:543} INFO - Closing down clientserver connection
[2024-05-17T16:20:51.683+0530] {java_gateway.py:1052} INFO - Exception while sending command.
Traceback (most recent call last):
  File "/Users/aswin/anaconda3/envs/bdl/lib/python3.10/site-packages/py4j/clientserver.py", line 503, in send_command
    self.socket.sendall(command.encode("utf-8"))
BrokenPipeError: [Errno 32] Broken pipe

During handling of the above exception, another exception occurred:

Traceback (most recent call last):
  File "/Users/aswin/anaconda3/envs/bdl/lib/python3.10/site-packages/py4j/java_gateway.py", line 1038, in send_command
    response = connection.send_command(command)
  File "/Users/aswin/anaconda3/envs/bdl/lib/python3.10/site-packages/py4j/clientserver.py", line 506, in send_command
    raise Py4JNetworkError(
py4j.protocol.Py4JNetworkError: Error while sending
[2024-05-17T16:20:51.685+0530] {clientserver.py:543} INFO - Closing down clientserver connection
[2024-05-17T16:20:53.019+0530] {taskinstance.py:1824} ERROR - Task failed with exception
Traceback (most recent call last):
  File "/Users/aswin/anaconda3/envs/bdl/lib/python3.10/site-packages/airflow/operators/python.py", line 181, in execute
    return_value = self.execute_callable()
  File "/Users/aswin/anaconda3/envs/bdl/lib/python3.10/site-packages/airflow/operators/python.py", line 198, in execute_callable
    return self.python_callable(*self.op_args, **self.op_kwargs)
  File "/Users/aswin/Downloads/Courses/Big Data Lab/Project/dags/iris_prediction.py", line 74, in train_model
    mlflow.log_artifact("preprocessed_data.parquet", artifact_path="data")
  File "/Users/aswin/anaconda3/envs/bdl/lib/python3.10/site-packages/mlflow/tracking/fluent.py", line 1068, in log_artifact
    MlflowClient().log_artifact(run_id, local_path, artifact_path)
  File "/Users/aswin/anaconda3/envs/bdl/lib/python3.10/site-packages/mlflow/tracking/client.py", line 1215, in log_artifact
    self._tracking_client.log_artifact(run_id, local_path, artifact_path)
  File "/Users/aswin/anaconda3/envs/bdl/lib/python3.10/site-packages/mlflow/tracking/_tracking_service/client.py", line 557, in log_artifact
    artifact_repo.log_artifact(local_path, artifact_path)
  File "/Users/aswin/anaconda3/envs/bdl/lib/python3.10/site-packages/mlflow/store/artifact/local_artifact_repo.py", line 39, in log_artifact
    shutil.copy2(local_file, os.path.join(artifact_dir, os.path.basename(local_file)))
  File "/Users/aswin/anaconda3/envs/bdl/lib/python3.10/shutil.py", line 434, in copy2
    copyfile(src, dst, follow_symlinks=follow_symlinks)
  File "/Users/aswin/anaconda3/envs/bdl/lib/python3.10/shutil.py", line 254, in copyfile
    with open(src, 'rb') as fsrc:
FileNotFoundError: [Errno 2] No such file or directory: 'preprocessed_data.parquet'
[2024-05-17T16:20:53.025+0530] {taskinstance.py:1345} INFO - Marking task as FAILED. dag_id=iris_classification, task_id=train_model, execution_date=20240517T104529, start_date=20240517T105051, end_date=20240517T105053
[2024-05-17T16:20:53.117+0530] {standard_task_runner.py:104} ERROR - Failed to execute job 13 for task train_model ([Errno 2] No such file or directory: 'preprocessed_data.parquet'; 33774)
[2024-05-17T16:20:53.160+0530] {local_task_job_runner.py:225} INFO - Task exited with return code 1
[2024-05-17T16:20:53.168+0530] {taskinstance.py:2651} INFO - 0 downstream tasks scheduled from follow-on schedule check
