[2024-05-17T20:35:56.766+0530] {taskinstance.py:1103} INFO - Dependencies all met for dep_context=non-requeueable deps ti=<TaskInstance: iris_classification.train_model manual__2024-05-17T15:05:43.517800+00:00 [queued]>
[2024-05-17T20:35:56.768+0530] {taskinstance.py:1103} INFO - Dependencies all met for dep_context=requeueable deps ti=<TaskInstance: iris_classification.train_model manual__2024-05-17T15:05:43.517800+00:00 [queued]>
[2024-05-17T20:35:56.769+0530] {taskinstance.py:1308} INFO - Starting attempt 1 of 2
[2024-05-17T20:35:56.773+0530] {taskinstance.py:1327} INFO - Executing <Task(PythonOperator): train_model> on 2024-05-17 15:05:43.517800+00:00
[2024-05-17T20:35:56.776+0530] {standard_task_runner.py:57} INFO - Started process 17080 to run task
[2024-05-17T20:35:56.777+0530] {clientserver.py:543} INFO - Closing down clientserver connection
[2024-05-17T20:35:56.779+0530] {standard_task_runner.py:84} INFO - Running: ['airflow', 'tasks', 'run', 'iris_classification', 'train_model', 'manual__2024-05-17T15:05:43.517800+00:00', '--job-id', '25', '--raw', '--subdir', 'DAGS_FOLDER/iris_prediction.py', '--cfg-path', '/var/folders/fy/4q0txy357vvc35bhsxlfyr8c0000gn/T/tmpi4dq7bbi']
[2024-05-17T20:35:56.780+0530] {standard_task_runner.py:85} INFO - Job 25: Subtask train_model
[2024-05-17T20:35:56.796+0530] {task_command.py:410} INFO - Running <TaskInstance: iris_classification.train_model manual__2024-05-17T15:05:43.517800+00:00 [running]> on host aswins-macbook-air.local
[2024-05-17T20:35:56.818+0530] {taskinstance.py:1545} INFO - Exporting env vars: AIRFLOW_CTX_DAG_OWNER='airflow' AIRFLOW_CTX_DAG_ID='iris_classification' AIRFLOW_CTX_TASK_ID='train_model' AIRFLOW_CTX_EXECUTION_DATE='2024-05-17T15:05:43.517800+00:00' AIRFLOW_CTX_TRY_NUMBER='1' AIRFLOW_CTX_DAG_RUN_ID='manual__2024-05-17T15:05:43.517800+00:00'
[2024-05-17T20:35:58.510+0530] {taskinstance.py:1824} ERROR - Task failed with exception
Traceback (most recent call last):
  File "/Users/aswin/anaconda3/envs/bdl/lib/python3.10/site-packages/airflow/operators/python.py", line 181, in execute
    return_value = self.execute_callable()
  File "/Users/aswin/anaconda3/envs/bdl/lib/python3.10/site-packages/airflow/operators/python.py", line 198, in execute_callable
    return self.python_callable(*self.op_args, **self.op_kwargs)
  File "/Users/aswin/Downloads/Courses/Big Data Lab/Project/dags/iris_prediction.py", line 81, in train_model
    model = pipeline.fit(train_data)
  File "/Users/aswin/anaconda3/envs/bdl/lib/python3.10/site-packages/pyspark/ml/base.py", line 205, in fit
    return self._fit(dataset)
  File "/Users/aswin/anaconda3/envs/bdl/lib/python3.10/site-packages/pyspark/ml/pipeline.py", line 134, in _fit
    model = stage.fit(dataset)
  File "/Users/aswin/anaconda3/envs/bdl/lib/python3.10/site-packages/pyspark/ml/base.py", line 205, in fit
    return self._fit(dataset)
  File "/Users/aswin/anaconda3/envs/bdl/lib/python3.10/site-packages/pyspark/ml/wrapper.py", line 381, in _fit
    java_model = self._fit_java(dataset)
  File "/Users/aswin/anaconda3/envs/bdl/lib/python3.10/site-packages/pyspark/ml/wrapper.py", line 378, in _fit_java
    return self._java_obj.fit(dataset._jdf)
  File "/Users/aswin/anaconda3/envs/bdl/lib/python3.10/site-packages/py4j/java_gateway.py", line 1322, in __call__
    return_value = get_return_value(
  File "/Users/aswin/anaconda3/envs/bdl/lib/python3.10/site-packages/pyspark/errors/exceptions/captured.py", line 185, in deco
    raise converted from None
pyspark.errors.exceptions.captured.IllegalArgumentException: feats does not exist. Available: sepal_length, sepal_width, petal_length, petal_width, label, features
[2024-05-17T20:35:58.518+0530] {taskinstance.py:1345} INFO - Marking task as UP_FOR_RETRY. dag_id=iris_classification, task_id=train_model, execution_date=20240517T150543, start_date=20240517T150556, end_date=20240517T150558
[2024-05-17T20:35:58.522+0530] {standard_task_runner.py:104} ERROR - Failed to execute job 25 for task train_model (feats does not exist. Available: sepal_length, sepal_width, petal_length, petal_width, label, features; 17080)
[2024-05-17T20:35:58.536+0530] {local_task_job_runner.py:225} INFO - Task exited with return code 1
[2024-05-17T20:35:58.542+0530] {taskinstance.py:2651} INFO - 0 downstream tasks scheduled from follow-on schedule check
