[2024-05-18T02:55:44.371+0530] {taskinstance.py:1956} INFO - Dependencies all met for dep_context=non-requeueable deps ti=<TaskInstance: iris_classification.train_model manual__2024-05-17T21:25:25.571965+00:00 [queued]>
[2024-05-18T02:55:44.374+0530] {taskinstance.py:1956} INFO - Dependencies all met for dep_context=requeueable deps ti=<TaskInstance: iris_classification.train_model manual__2024-05-17T21:25:25.571965+00:00 [queued]>
[2024-05-18T02:55:44.374+0530] {taskinstance.py:2170} INFO - Starting attempt 1 of 0
[2024-05-18T02:55:44.380+0530] {taskinstance.py:2191} INFO - Executing <Task(PythonOperator): train_model> on 2024-05-17 21:25:25.571965+00:00
[2024-05-18T02:55:44.384+0530] {standard_task_runner.py:60} INFO - Started process 13377 to run task
[2024-05-18T02:55:44.385+0530] {clientserver.py:543} INFO - Closing down clientserver connection
[2024-05-18T02:55:44.391+0530] {standard_task_runner.py:87} INFO - Running: ['airflow', 'tasks', 'run', 'iris_classification', 'train_model', 'manual__2024-05-17T21:25:25.571965+00:00', '--job-id', '71', '--raw', '--subdir', 'DAGS_FOLDER/main.py', '--cfg-path', '/var/folders/fy/4q0txy357vvc35bhsxlfyr8c0000gn/T/tmpn8yyv5cv']
[2024-05-18T02:55:44.392+0530] {standard_task_runner.py:88} INFO - Job 71: Subtask train_model
[2024-05-18T02:55:44.425+0530] {task_command.py:423} INFO - Running <TaskInstance: iris_classification.train_model manual__2024-05-17T21:25:25.571965+00:00 [running]> on host aswins-macbook-air.local
[2024-05-18T02:55:44.462+0530] {taskinstance.py:2480} INFO - Exporting env vars: AIRFLOW_CTX_DAG_OWNER='airflow' AIRFLOW_CTX_DAG_ID='iris_classification' AIRFLOW_CTX_TASK_ID='train_model' AIRFLOW_CTX_EXECUTION_DATE='2024-05-17T21:25:25.571965+00:00' AIRFLOW_CTX_TRY_NUMBER='1' AIRFLOW_CTX_DAG_RUN_ID='manual__2024-05-17T21:25:25.571965+00:00'
[2024-05-18T02:55:44.979+0530] {clientserver.py:505} INFO - Error while sending or receiving.
Traceback (most recent call last):
  File "/Users/aswin/anaconda3/lib/python3.10/site-packages/py4j/clientserver.py", line 503, in send_command
    self.socket.sendall(command.encode("utf-8"))
BrokenPipeError: [Errno 32] Broken pipe
[2024-05-18T02:55:44.986+0530] {clientserver.py:543} INFO - Closing down clientserver connection
[2024-05-18T02:55:44.987+0530] {java_gateway.py:1052} INFO - Exception while sending command.
Traceback (most recent call last):
  File "/Users/aswin/anaconda3/lib/python3.10/site-packages/py4j/clientserver.py", line 503, in send_command
    self.socket.sendall(command.encode("utf-8"))
BrokenPipeError: [Errno 32] Broken pipe

During handling of the above exception, another exception occurred:

Traceback (most recent call last):
  File "/Users/aswin/anaconda3/lib/python3.10/site-packages/py4j/java_gateway.py", line 1038, in send_command
    response = connection.send_command(command)
  File "/Users/aswin/anaconda3/lib/python3.10/site-packages/py4j/clientserver.py", line 506, in send_command
    raise Py4JNetworkError(
py4j.protocol.Py4JNetworkError: Error while sending
[2024-05-18T02:55:44.989+0530] {clientserver.py:543} INFO - Closing down clientserver connection
[2024-05-18T03:01:11.443+0530] {local_task_job_runner.py:302} WARNING - State of this instance has been externally set to None. Terminating instance.
[2024-05-18T03:01:11.450+0530] {process_utils.py:131} INFO - Sending Signals.SIGTERM to group 13377. PIDs of all processes in the group: [13377]
[2024-05-18T03:01:11.450+0530] {process_utils.py:86} INFO - Sending the signal Signals.SIGTERM to group 13377
[2024-05-18T03:02:11.456+0530] {process_utils.py:149} WARNING - process psutil.Process(pid=13377, name='python3.10', status='running', started='02:55:44') did not respond to SIGTERM. Trying SIGKILL
[2024-05-18T03:02:11.460+0530] {process_utils.py:86} INFO - Sending the signal Signals.SIGKILL to group 13377
[2024-05-18T03:02:11.489+0530] {process_utils.py:79} INFO - Process psutil.Process(pid=13377, name='python3.10', status='terminated', exitcode=<Negsignal.SIGKILL: -9>, started='02:55:44') (13377) terminated with exit code Negsignal.SIGKILL
[2024-05-18T03:02:11.490+0530] {standard_task_runner.py:175} ERROR - Job 71 was killed before it finished (likely due to running out of memory)
