[2024-05-18T11:29:56.053+0530] {taskinstance.py:1956} INFO - Dependencies all met for dep_context=non-requeueable deps ti=<TaskInstance: iris_classification.preprocess_data manual__2024-05-18T05:59:48.179336+00:00 [queued]>
[2024-05-18T11:29:56.058+0530] {taskinstance.py:1956} INFO - Dependencies all met for dep_context=requeueable deps ti=<TaskInstance: iris_classification.preprocess_data manual__2024-05-18T05:59:48.179336+00:00 [queued]>
[2024-05-18T11:29:56.058+0530] {taskinstance.py:2170} INFO - Starting attempt 1 of 0
[2024-05-18T11:29:56.067+0530] {taskinstance.py:2191} INFO - Executing <Task(PythonOperator): preprocess_data> on 2024-05-18 05:59:48.179336+00:00
[2024-05-18T11:29:56.071+0530] {standard_task_runner.py:60} INFO - Started process 31123 to run task
[2024-05-18T11:29:56.072+0530] {clientserver.py:543} INFO - Closing down clientserver connection
[2024-05-18T11:29:56.080+0530] {standard_task_runner.py:87} INFO - Running: ['airflow', 'tasks', 'run', 'iris_classification', 'preprocess_data', 'manual__2024-05-18T05:59:48.179336+00:00', '--job-id', '99', '--raw', '--subdir', 'DAGS_FOLDER/main.py', '--cfg-path', '/var/folders/fy/4q0txy357vvc35bhsxlfyr8c0000gn/T/tmpmkjpov1f']
[2024-05-18T11:29:56.082+0530] {standard_task_runner.py:88} INFO - Job 99: Subtask preprocess_data
[2024-05-18T11:29:56.132+0530] {task_command.py:423} INFO - Running <TaskInstance: iris_classification.preprocess_data manual__2024-05-18T05:59:48.179336+00:00 [running]> on host aswins-macbook-air.local
[2024-05-18T11:29:56.177+0530] {taskinstance.py:2480} INFO - Exporting env vars: AIRFLOW_CTX_DAG_OWNER='airflow' AIRFLOW_CTX_DAG_ID='iris_classification' AIRFLOW_CTX_TASK_ID='preprocess_data' AIRFLOW_CTX_EXECUTION_DATE='2024-05-18T05:59:48.179336+00:00' AIRFLOW_CTX_TRY_NUMBER='1' AIRFLOW_CTX_DAG_RUN_ID='manual__2024-05-18T05:59:48.179336+00:00'
[2024-05-18T11:29:56.518+0530] {clientserver.py:505} INFO - Error while sending or receiving.
Traceback (most recent call last):
  File "/Users/aswin/anaconda3/lib/python3.10/site-packages/py4j/clientserver.py", line 503, in send_command
    self.socket.sendall(command.encode("utf-8"))
BrokenPipeError: [Errno 32] Broken pipe
[2024-05-18T11:29:56.521+0530] {clientserver.py:543} INFO - Closing down clientserver connection
[2024-05-18T11:29:56.521+0530] {java_gateway.py:1052} INFO - Exception while sending command.
Traceback (most recent call last):
  File "/Users/aswin/anaconda3/lib/python3.10/site-packages/py4j/clientserver.py", line 503, in send_command
    self.socket.sendall(command.encode("utf-8"))
BrokenPipeError: [Errno 32] Broken pipe

During handling of the above exception, another exception occurred:

Traceback (most recent call last):
  File "/Users/aswin/anaconda3/lib/python3.10/site-packages/py4j/java_gateway.py", line 1038, in send_command
    response = connection.send_command(command)
  File "/Users/aswin/anaconda3/lib/python3.10/site-packages/py4j/clientserver.py", line 506, in send_command
    raise Py4JNetworkError(
py4j.protocol.Py4JNetworkError: Error while sending
[2024-05-18T11:29:56.523+0530] {clientserver.py:543} INFO - Closing down clientserver connection
[2024-05-18T11:29:57.212+0530] {taskinstance.py:2698} ERROR - Task failed with exception
Traceback (most recent call last):
  File "/Users/aswin/anaconda3/lib/python3.10/site-packages/airflow/models/taskinstance.py", line 433, in _execute_task
    result = execute_callable(context=context, **execute_callable_kwargs)
  File "/Users/aswin/anaconda3/lib/python3.10/site-packages/airflow/operators/python.py", line 199, in execute
    return_value = self.execute_callable()
  File "/Users/aswin/anaconda3/lib/python3.10/site-packages/airflow/operators/python.py", line 216, in execute_callable
    return self.python_callable(*self.op_args, **self.op_kwargs)
  File "/Users/aswin/Downloads/Courses/Big Data Lab/Project/dags/main.py", line 68, in preprocess_data
    iris_data = spark.read.csv(iris_data_path, header=False, inferSchema=True)
  File "/Users/aswin/anaconda3/lib/python3.10/site-packages/pyspark/sql/readwriter.py", line 740, in csv
    return self._df(self._jreader.csv(self._spark._sc._jvm.PythonUtils.toSeq(path)))
  File "/Users/aswin/anaconda3/lib/python3.10/site-packages/py4j/java_gateway.py", line 1322, in __call__
    return_value = get_return_value(
  File "/Users/aswin/anaconda3/lib/python3.10/site-packages/pyspark/errors/exceptions/captured.py", line 185, in deco
    raise converted from None
pyspark.errors.exceptions.captured.AnalysisException: [PATH_NOT_FOUND] Path does not exist: file:/dataset/iris.csv.
[2024-05-18T11:29:57.239+0530] {taskinstance.py:1138} INFO - Marking task as FAILED. dag_id=iris_classification, task_id=preprocess_data, execution_date=20240518T055948, start_date=20240518T055956, end_date=20240518T055957
[2024-05-18T11:29:57.250+0530] {standard_task_runner.py:107} ERROR - Failed to execute job 99 for task preprocess_data ([PATH_NOT_FOUND] Path does not exist: file:/dataset/iris.csv.; 31123)
[2024-05-18T11:29:57.279+0530] {local_task_job_runner.py:234} INFO - Task exited with return code 1
[2024-05-18T11:29:57.293+0530] {taskinstance.py:3280} INFO - 0 downstream tasks scheduled from follow-on schedule check
