[2024-05-18T11:36:37.199+0530] {taskinstance.py:1956} INFO - Dependencies all met for dep_context=non-requeueable deps ti=<TaskInstance: iris_classification.train_model manual__2024-05-18T06:06:06.404803+00:00 [queued]>
[2024-05-18T11:36:37.204+0530] {taskinstance.py:1956} INFO - Dependencies all met for dep_context=requeueable deps ti=<TaskInstance: iris_classification.train_model manual__2024-05-18T06:06:06.404803+00:00 [queued]>
[2024-05-18T11:36:37.204+0530] {taskinstance.py:2170} INFO - Starting attempt 1 of 0
[2024-05-18T11:36:37.212+0530] {taskinstance.py:2191} INFO - Executing <Task(PythonOperator): train_model> on 2024-05-18 06:06:06.404803+00:00
[2024-05-18T11:36:37.217+0530] {standard_task_runner.py:60} INFO - Started process 32753 to run task
[2024-05-18T11:36:37.218+0530] {clientserver.py:543} INFO - Closing down clientserver connection
[2024-05-18T11:36:37.225+0530] {standard_task_runner.py:87} INFO - Running: ['airflow', 'tasks', 'run', 'iris_classification', 'train_model', 'manual__2024-05-18T06:06:06.404803+00:00', '--job-id', '104', '--raw', '--subdir', 'DAGS_FOLDER/main.py', '--cfg-path', '/var/folders/fy/4q0txy357vvc35bhsxlfyr8c0000gn/T/tmpe68pfn4e']
[2024-05-18T11:36:37.228+0530] {standard_task_runner.py:88} INFO - Job 104: Subtask train_model
[2024-05-18T11:36:37.267+0530] {task_command.py:423} INFO - Running <TaskInstance: iris_classification.train_model manual__2024-05-18T06:06:06.404803+00:00 [running]> on host aswins-macbook-air.local
[2024-05-18T11:36:37.312+0530] {taskinstance.py:2480} INFO - Exporting env vars: AIRFLOW_CTX_DAG_OWNER='airflow' AIRFLOW_CTX_DAG_ID='iris_classification' AIRFLOW_CTX_TASK_ID='train_model' AIRFLOW_CTX_EXECUTION_DATE='2024-05-18T06:06:06.404803+00:00' AIRFLOW_CTX_TRY_NUMBER='1' AIRFLOW_CTX_DAG_RUN_ID='manual__2024-05-18T06:06:06.404803+00:00'
[2024-05-18T11:36:37.664+0530] {clientserver.py:505} INFO - Error while sending or receiving.
Traceback (most recent call last):
  File "/Users/aswin/anaconda3/lib/python3.10/site-packages/py4j/clientserver.py", line 503, in send_command
    self.socket.sendall(command.encode("utf-8"))
BrokenPipeError: [Errno 32] Broken pipe
[2024-05-18T11:36:37.667+0530] {clientserver.py:543} INFO - Closing down clientserver connection
[2024-05-18T11:36:37.667+0530] {java_gateway.py:1052} INFO - Exception while sending command.
Traceback (most recent call last):
  File "/Users/aswin/anaconda3/lib/python3.10/site-packages/py4j/clientserver.py", line 503, in send_command
    self.socket.sendall(command.encode("utf-8"))
BrokenPipeError: [Errno 32] Broken pipe

During handling of the above exception, another exception occurred:

Traceback (most recent call last):
  File "/Users/aswin/anaconda3/lib/python3.10/site-packages/py4j/java_gateway.py", line 1038, in send_command
    response = connection.send_command(command)
  File "/Users/aswin/anaconda3/lib/python3.10/site-packages/py4j/clientserver.py", line 506, in send_command
    raise Py4JNetworkError(
py4j.protocol.Py4JNetworkError: Error while sending
[2024-05-18T11:36:37.670+0530] {clientserver.py:543} INFO - Closing down clientserver connection
[2024-05-18T11:40:38.720+0530] {local_task_job_runner.py:302} WARNING - State of this instance has been externally set to failed. Terminating instance.
[2024-05-18T11:40:38.728+0530] {process_utils.py:131} INFO - Sending Signals.SIGTERM to group 32753. PIDs of all processes in the group: [32753]
[2024-05-18T11:40:38.729+0530] {process_utils.py:86} INFO - Sending the signal Signals.SIGTERM to group 32753
[2024-05-18T11:41:38.743+0530] {process_utils.py:149} WARNING - process psutil.Process(pid=32753, name='python3.10', status='running', started='11:36:37') did not respond to SIGTERM. Trying SIGKILL
[2024-05-18T11:41:38.745+0530] {process_utils.py:86} INFO - Sending the signal Signals.SIGKILL to group 32753
[2024-05-18T11:41:38.762+0530] {process_utils.py:79} INFO - Process psutil.Process(pid=32753, name='python3.10', status='terminated', exitcode=<Negsignal.SIGKILL: -9>, started='11:36:37') (32753) terminated with exit code Negsignal.SIGKILL
[2024-05-18T11:41:38.762+0530] {standard_task_runner.py:175} ERROR - Job 104 was killed before it finished (likely due to running out of memory)
