[2024-05-18T14:17:04.324+0530] {local_task_job_runner.py:120} INFO - ::group::Pre task execution logs
[2024-05-18T14:17:04.354+0530] {taskinstance.py:2076} INFO - Dependencies all met for dep_context=non-requeueable deps ti=<TaskInstance: iris_classification.preprocess_data manual__2024-05-18T08:46:55.817536+00:00 [queued]>
[2024-05-18T14:17:04.359+0530] {taskinstance.py:2076} INFO - Dependencies all met for dep_context=requeueable deps ti=<TaskInstance: iris_classification.preprocess_data manual__2024-05-18T08:46:55.817536+00:00 [queued]>
[2024-05-18T14:17:04.359+0530] {taskinstance.py:2306} INFO - Starting attempt 1 of 0
[2024-05-18T14:17:04.368+0530] {taskinstance.py:2330} INFO - Executing <Task(PythonOperator): preprocess_data> on 2024-05-18 08:46:55.817536+00:00
[2024-05-18T14:17:04.373+0530] {standard_task_runner.py:63} INFO - Started process 69444 to run task
[2024-05-18T14:17:04.375+0530] {clientserver.py:543} INFO - Closing down clientserver connection
[2024-05-18T14:17:04.380+0530] {standard_task_runner.py:90} INFO - Running: ['airflow', 'tasks', 'run', 'iris_classification', 'preprocess_data', 'manual__2024-05-18T08:46:55.817536+00:00', '--job-id', '114', '--raw', '--subdir', 'DAGS_FOLDER/main.py', '--cfg-path', '/var/folders/fy/4q0txy357vvc35bhsxlfyr8c0000gn/T/tmpzq8bob3i']
[2024-05-18T14:17:04.382+0530] {standard_task_runner.py:91} INFO - Job 114: Subtask preprocess_data
[2024-05-18T14:17:04.432+0530] {task_command.py:426} INFO - Running <TaskInstance: iris_classification.preprocess_data manual__2024-05-18T08:46:55.817536+00:00 [running]> on host aswins-macbook-air.local
[2024-05-18T14:17:04.492+0530] {taskinstance.py:2648} INFO - Exporting env vars: AIRFLOW_CTX_DAG_OWNER='airflow' AIRFLOW_CTX_DAG_ID='iris_classification' AIRFLOW_CTX_TASK_ID='preprocess_data' AIRFLOW_CTX_EXECUTION_DATE='2024-05-18T08:46:55.817536+00:00' AIRFLOW_CTX_TRY_NUMBER='1' AIRFLOW_CTX_DAG_RUN_ID='manual__2024-05-18T08:46:55.817536+00:00'
[2024-05-18T14:17:04.493+0530] {taskinstance.py:430} INFO - ::endgroup::
[2024-05-18T14:17:04.688+0530] {clientserver.py:505} INFO - Error while sending or receiving.
Traceback (most recent call last):
  File "/Users/aswin/anaconda3/envs/bdl/lib/python3.10/site-packages/py4j/clientserver.py", line 503, in send_command
    self.socket.sendall(command.encode("utf-8"))
BrokenPipeError: [Errno 32] Broken pipe
[2024-05-18T14:17:04.692+0530] {clientserver.py:543} INFO - Closing down clientserver connection
[2024-05-18T14:17:04.692+0530] {java_gateway.py:1052} INFO - Exception while sending command.
Traceback (most recent call last):
  File "/Users/aswin/anaconda3/envs/bdl/lib/python3.10/site-packages/py4j/clientserver.py", line 503, in send_command
    self.socket.sendall(command.encode("utf-8"))
BrokenPipeError: [Errno 32] Broken pipe

During handling of the above exception, another exception occurred:

Traceback (most recent call last):
  File "/Users/aswin/anaconda3/envs/bdl/lib/python3.10/site-packages/py4j/java_gateway.py", line 1038, in send_command
    response = connection.send_command(command)
  File "/Users/aswin/anaconda3/envs/bdl/lib/python3.10/site-packages/py4j/clientserver.py", line 506, in send_command
    raise Py4JNetworkError(
py4j.protocol.Py4JNetworkError: Error while sending
[2024-05-18T14:17:04.695+0530] {clientserver.py:543} INFO - Closing down clientserver connection
[2024-05-18T14:17:10.503+0530] {taskinstance.py:441} INFO - ::group::Post task execution logs
[2024-05-18T14:17:10.504+0530] {taskinstance.py:2905} ERROR - Task failed with exception
Traceback (most recent call last):
  File "/Users/aswin/anaconda3/envs/bdl/lib/python3.10/site-packages/airflow/models/taskinstance.py", line 465, in _execute_task
    result = _execute_callable(context=context, **execute_callable_kwargs)
  File "/Users/aswin/anaconda3/envs/bdl/lib/python3.10/site-packages/airflow/models/taskinstance.py", line 432, in _execute_callable
    return execute_callable(context=context, **execute_callable_kwargs)
  File "/Users/aswin/anaconda3/envs/bdl/lib/python3.10/site-packages/airflow/models/baseoperator.py", line 400, in wrapper
    return func(self, *args, **kwargs)
  File "/Users/aswin/anaconda3/envs/bdl/lib/python3.10/site-packages/airflow/operators/python.py", line 235, in execute
    return_value = self.execute_callable()
  File "/Users/aswin/anaconda3/envs/bdl/lib/python3.10/site-packages/airflow/operators/python.py", line 252, in execute_callable
    return self.python_callable(*self.op_args, **self.op_kwargs)
  File "/Users/aswin/Downloads/Courses/Big Data Lab/Project/dags/main.py", line 71, in preprocess_data
    labelIndexer.save(label_model_path)
  File "/Users/aswin/anaconda3/envs/bdl/lib/python3.10/site-packages/pyspark/ml/util.py", line 262, in save
    self.write().save(path)
  File "/Users/aswin/anaconda3/envs/bdl/lib/python3.10/site-packages/pyspark/ml/util.py", line 213, in save
    self._jwrite.save(path)
  File "/Users/aswin/anaconda3/envs/bdl/lib/python3.10/site-packages/py4j/java_gateway.py", line 1322, in __call__
    return_value = get_return_value(
  File "/Users/aswin/anaconda3/envs/bdl/lib/python3.10/site-packages/pyspark/errors/exceptions/captured.py", line 179, in deco
    return f(*a, **kw)
  File "/Users/aswin/anaconda3/envs/bdl/lib/python3.10/site-packages/py4j/protocol.py", line 326, in get_return_value
    raise Py4JJavaError(
py4j.protocol.Py4JJavaError: An error occurred while calling o91.save.
: java.io.IOException: Path /Users/aswin/Downloads/Courses/Big Data Lab/Project/model/label_model already exists. To overwrite it, please use write.overwrite().save(path) for Scala and use write().overwrite().save(path) for Java and Python.
	at org.apache.spark.ml.util.FileSystemOverwrite.handleOverwrite(ReadWrite.scala:683)
	at org.apache.spark.ml.util.MLWriter.save(ReadWrite.scala:167)
	at java.base/jdk.internal.reflect.NativeMethodAccessorImpl.invoke0(Native Method)
	at java.base/jdk.internal.reflect.NativeMethodAccessorImpl.invoke(NativeMethodAccessorImpl.java:75)
	at java.base/jdk.internal.reflect.DelegatingMethodAccessorImpl.invoke(DelegatingMethodAccessorImpl.java:52)
	at java.base/java.lang.reflect.Method.invoke(Method.java:578)
	at py4j.reflection.MethodInvoker.invoke(MethodInvoker.java:244)
	at py4j.reflection.ReflectionEngine.invoke(ReflectionEngine.java:374)
	at py4j.Gateway.invoke(Gateway.java:282)
	at py4j.commands.AbstractCommand.invokeMethod(AbstractCommand.java:132)
	at py4j.commands.CallCommand.execute(CallCommand.java:79)
	at py4j.ClientServerConnection.waitForCommands(ClientServerConnection.java:182)
	at py4j.ClientServerConnection.run(ClientServerConnection.java:106)
	at java.base/java.lang.Thread.run(Thread.java:1623)

[2024-05-18T14:17:10.516+0530] {taskinstance.py:1206} INFO - Marking task as FAILED. dag_id=iris_classification, task_id=preprocess_data, run_id=manual__2024-05-18T08:46:55.817536+00:00, execution_date=20240518T084655, start_date=20240518T084704, end_date=20240518T084710
[2024-05-18T14:17:10.525+0530] {standard_task_runner.py:110} ERROR - Failed to execute job 114 for task preprocess_data (An error occurred while calling o91.save.
: java.io.IOException: Path /Users/aswin/Downloads/Courses/Big Data Lab/Project/model/label_model already exists. To overwrite it, please use write.overwrite().save(path) for Scala and use write().overwrite().save(path) for Java and Python.
	at org.apache.spark.ml.util.FileSystemOverwrite.handleOverwrite(ReadWrite.scala:683)
	at org.apache.spark.ml.util.MLWriter.save(ReadWrite.scala:167)
	at java.base/jdk.internal.reflect.NativeMethodAccessorImpl.invoke0(Native Method)
	at java.base/jdk.internal.reflect.NativeMethodAccessorImpl.invoke(NativeMethodAccessorImpl.java:75)
	at java.base/jdk.internal.reflect.DelegatingMethodAccessorImpl.invoke(DelegatingMethodAccessorImpl.java:52)
	at java.base/java.lang.reflect.Method.invoke(Method.java:578)
	at py4j.reflection.MethodInvoker.invoke(MethodInvoker.java:244)
	at py4j.reflection.ReflectionEngine.invoke(ReflectionEngine.java:374)
	at py4j.Gateway.invoke(Gateway.java:282)
	at py4j.commands.AbstractCommand.invokeMethod(AbstractCommand.java:132)
	at py4j.commands.CallCommand.execute(CallCommand.java:79)
	at py4j.ClientServerConnection.waitForCommands(ClientServerConnection.java:182)
	at py4j.ClientServerConnection.run(ClientServerConnection.java:106)
	at java.base/java.lang.Thread.run(Thread.java:1623)
; 69444)
[2024-05-18T14:17:10.572+0530] {local_task_job_runner.py:240} INFO - Task exited with return code 1
[2024-05-18T14:17:10.591+0530] {taskinstance.py:3498} INFO - 0 downstream tasks scheduled from follow-on schedule check
[2024-05-18T14:17:10.594+0530] {local_task_job_runner.py:222} INFO - ::endgroup::
