[2024-05-18T11:08:22.447+0530] {taskinstance.py:1956} INFO - Dependencies all met for dep_context=non-requeueable deps ti=<TaskInstance: iris_classification.preprocess_data manual__2024-05-18T05:38:14.795774+00:00 [queued]>
[2024-05-18T11:08:22.452+0530] {taskinstance.py:1956} INFO - Dependencies all met for dep_context=requeueable deps ti=<TaskInstance: iris_classification.preprocess_data manual__2024-05-18T05:38:14.795774+00:00 [queued]>
[2024-05-18T11:08:22.452+0530] {taskinstance.py:2170} INFO - Starting attempt 1 of 0
[2024-05-18T11:08:22.461+0530] {taskinstance.py:2191} INFO - Executing <Task(PythonOperator): preprocess_data> on 2024-05-18 05:38:14.795774+00:00
[2024-05-18T11:08:22.466+0530] {standard_task_runner.py:60} INFO - Started process 25965 to run task
[2024-05-18T11:08:22.467+0530] {clientserver.py:543} INFO - Closing down clientserver connection
[2024-05-18T11:08:22.473+0530] {standard_task_runner.py:87} INFO - Running: ['airflow', 'tasks', 'run', 'iris_classification', 'preprocess_data', 'manual__2024-05-18T05:38:14.795774+00:00', '--job-id', '86', '--raw', '--subdir', 'DAGS_FOLDER/main.py', '--cfg-path', '/var/folders/fy/4q0txy357vvc35bhsxlfyr8c0000gn/T/tmp2wayaxxf']
[2024-05-18T11:08:22.476+0530] {standard_task_runner.py:88} INFO - Job 86: Subtask preprocess_data
[2024-05-18T11:08:22.527+0530] {task_command.py:423} INFO - Running <TaskInstance: iris_classification.preprocess_data manual__2024-05-18T05:38:14.795774+00:00 [running]> on host aswins-macbook-air.local
[2024-05-18T11:08:22.586+0530] {taskinstance.py:2480} INFO - Exporting env vars: AIRFLOW_CTX_DAG_OWNER='airflow' AIRFLOW_CTX_DAG_ID='iris_classification' AIRFLOW_CTX_TASK_ID='preprocess_data' AIRFLOW_CTX_EXECUTION_DATE='2024-05-18T05:38:14.795774+00:00' AIRFLOW_CTX_TRY_NUMBER='1' AIRFLOW_CTX_DAG_RUN_ID='manual__2024-05-18T05:38:14.795774+00:00'
[2024-05-18T11:08:22.830+0530] {clientserver.py:505} INFO - Error while sending or receiving.
Traceback (most recent call last):
  File "/Users/aswin/anaconda3/lib/python3.10/site-packages/py4j/clientserver.py", line 503, in send_command
    self.socket.sendall(command.encode("utf-8"))
BrokenPipeError: [Errno 32] Broken pipe
[2024-05-18T11:08:22.833+0530] {clientserver.py:543} INFO - Closing down clientserver connection
[2024-05-18T11:08:22.833+0530] {java_gateway.py:1052} INFO - Exception while sending command.
Traceback (most recent call last):
  File "/Users/aswin/anaconda3/lib/python3.10/site-packages/py4j/clientserver.py", line 503, in send_command
    self.socket.sendall(command.encode("utf-8"))
BrokenPipeError: [Errno 32] Broken pipe

During handling of the above exception, another exception occurred:

Traceback (most recent call last):
  File "/Users/aswin/anaconda3/lib/python3.10/site-packages/py4j/java_gateway.py", line 1038, in send_command
    response = connection.send_command(command)
  File "/Users/aswin/anaconda3/lib/python3.10/site-packages/py4j/clientserver.py", line 506, in send_command
    raise Py4JNetworkError(
py4j.protocol.Py4JNetworkError: Error while sending
[2024-05-18T11:08:22.836+0530] {clientserver.py:543} INFO - Closing down clientserver connection
[2024-05-18T11:08:29.239+0530] {python.py:201} INFO - Done. Returned value was: None
[2024-05-18T11:08:29.251+0530] {taskinstance.py:1138} INFO - Marking task as SUCCESS. dag_id=iris_classification, task_id=preprocess_data, execution_date=20240518T053814, start_date=20240518T053822, end_date=20240518T053829
[2024-05-18T11:08:29.286+0530] {local_task_job_runner.py:234} INFO - Task exited with return code 0
[2024-05-18T11:08:29.298+0530] {taskinstance.py:3280} INFO - 1 downstream tasks scheduled from follow-on schedule check
