[2024-05-18T11:08:35.571+0530] {taskinstance.py:1956} INFO - Dependencies all met for dep_context=non-requeueable deps ti=<TaskInstance: iris_classification.train_model manual__2024-05-18T05:38:14.795774+00:00 [queued]>
[2024-05-18T11:08:35.574+0530] {taskinstance.py:1956} INFO - Dependencies all met for dep_context=requeueable deps ti=<TaskInstance: iris_classification.train_model manual__2024-05-18T05:38:14.795774+00:00 [queued]>
[2024-05-18T11:08:35.574+0530] {taskinstance.py:2170} INFO - Starting attempt 1 of 0
[2024-05-18T11:08:35.580+0530] {taskinstance.py:2191} INFO - Executing <Task(PythonOperator): train_model> on 2024-05-18 05:38:14.795774+00:00
[2024-05-18T11:08:35.584+0530] {standard_task_runner.py:60} INFO - Started process 26060 to run task
[2024-05-18T11:08:35.585+0530] {clientserver.py:543} INFO - Closing down clientserver connection
[2024-05-18T11:08:35.590+0530] {standard_task_runner.py:87} INFO - Running: ['airflow', 'tasks', 'run', 'iris_classification', 'train_model', 'manual__2024-05-18T05:38:14.795774+00:00', '--job-id', '87', '--raw', '--subdir', 'DAGS_FOLDER/main.py', '--cfg-path', '/var/folders/fy/4q0txy357vvc35bhsxlfyr8c0000gn/T/tmp2ketsa1m']
[2024-05-18T11:08:35.592+0530] {standard_task_runner.py:88} INFO - Job 87: Subtask train_model
[2024-05-18T11:08:35.617+0530] {task_command.py:423} INFO - Running <TaskInstance: iris_classification.train_model manual__2024-05-18T05:38:14.795774+00:00 [running]> on host aswins-macbook-air.local
[2024-05-18T11:08:35.647+0530] {taskinstance.py:2480} INFO - Exporting env vars: AIRFLOW_CTX_DAG_OWNER='airflow' AIRFLOW_CTX_DAG_ID='iris_classification' AIRFLOW_CTX_TASK_ID='train_model' AIRFLOW_CTX_EXECUTION_DATE='2024-05-18T05:38:14.795774+00:00' AIRFLOW_CTX_TRY_NUMBER='1' AIRFLOW_CTX_DAG_RUN_ID='manual__2024-05-18T05:38:14.795774+00:00'
[2024-05-18T11:08:36.402+0530] {clientserver.py:505} INFO - Error while sending or receiving.
Traceback (most recent call last):
  File "/Users/aswin/anaconda3/lib/python3.10/site-packages/py4j/clientserver.py", line 503, in send_command
    self.socket.sendall(command.encode("utf-8"))
BrokenPipeError: [Errno 32] Broken pipe
[2024-05-18T11:08:36.405+0530] {clientserver.py:543} INFO - Closing down clientserver connection
[2024-05-18T11:08:36.406+0530] {java_gateway.py:1052} INFO - Exception while sending command.
Traceback (most recent call last):
  File "/Users/aswin/anaconda3/lib/python3.10/site-packages/py4j/clientserver.py", line 503, in send_command
    self.socket.sendall(command.encode("utf-8"))
BrokenPipeError: [Errno 32] Broken pipe

During handling of the above exception, another exception occurred:

Traceback (most recent call last):
  File "/Users/aswin/anaconda3/lib/python3.10/site-packages/py4j/java_gateway.py", line 1038, in send_command
    response = connection.send_command(command)
  File "/Users/aswin/anaconda3/lib/python3.10/site-packages/py4j/clientserver.py", line 506, in send_command
    raise Py4JNetworkError(
py4j.protocol.Py4JNetworkError: Error while sending
[2024-05-18T11:08:36.408+0530] {clientserver.py:543} INFO - Closing down clientserver connection
[2024-05-18T11:10:01.133+0530] {local_task_job_runner.py:302} WARNING - State of this instance has been externally set to None. Terminating instance.
[2024-05-18T11:10:01.140+0530] {process_utils.py:131} INFO - Sending Signals.SIGTERM to group 26060. PIDs of all processes in the group: [26060]
[2024-05-18T11:10:01.141+0530] {process_utils.py:86} INFO - Sending the signal Signals.SIGTERM to group 26060
[2024-05-18T11:11:01.173+0530] {process_utils.py:149} WARNING - process psutil.Process(pid=26060, name='python3.10', status='running', started='11:08:35') did not respond to SIGTERM. Trying SIGKILL
[2024-05-18T11:11:01.176+0530] {process_utils.py:86} INFO - Sending the signal Signals.SIGKILL to group 26060
[2024-05-18T11:11:01.193+0530] {process_utils.py:79} INFO - Process psutil.Process(pid=26060, name='python3.10', status='terminated', exitcode=<Negsignal.SIGKILL: -9>, started='11:08:35') (26060) terminated with exit code Negsignal.SIGKILL
[2024-05-18T11:11:01.193+0530] {standard_task_runner.py:175} ERROR - Job 87 was killed before it finished (likely due to running out of memory)
