[2024-05-17T16:11:30.332+0530] {taskinstance.py:1103} INFO - Dependencies all met for dep_context=non-requeueable deps ti=<TaskInstance: iris_classification.preprocess_data manual__2024-05-17T10:41:24.581535+00:00 [queued]>
[2024-05-17T16:11:30.334+0530] {taskinstance.py:1103} INFO - Dependencies all met for dep_context=requeueable deps ti=<TaskInstance: iris_classification.preprocess_data manual__2024-05-17T10:41:24.581535+00:00 [queued]>
[2024-05-17T16:11:30.334+0530] {taskinstance.py:1308} INFO - Starting attempt 1 of 2
[2024-05-17T16:11:30.338+0530] {taskinstance.py:1327} INFO - Executing <Task(PythonOperator): preprocess_data> on 2024-05-17 10:41:24.581535+00:00
[2024-05-17T16:11:30.341+0530] {standard_task_runner.py:57} INFO - Started process 31309 to run task
[2024-05-17T16:11:30.342+0530] {clientserver.py:543} INFO - Closing down clientserver connection
[2024-05-17T16:11:30.345+0530] {standard_task_runner.py:84} INFO - Running: ['airflow', 'tasks', 'run', 'iris_classification', 'preprocess_data', 'manual__2024-05-17T10:41:24.581535+00:00', '--job-id', '8', '--raw', '--subdir', 'DAGS_FOLDER/iris_prediction.py', '--cfg-path', '/var/folders/fy/4q0txy357vvc35bhsxlfyr8c0000gn/T/tmpd5ly15o9']
[2024-05-17T16:11:30.346+0530] {standard_task_runner.py:85} INFO - Job 8: Subtask preprocess_data
[2024-05-17T16:11:30.362+0530] {task_command.py:410} INFO - Running <TaskInstance: iris_classification.preprocess_data manual__2024-05-17T10:41:24.581535+00:00 [running]> on host aswins-macbook-air.local
[2024-05-17T16:11:30.383+0530] {taskinstance.py:1545} INFO - Exporting env vars: AIRFLOW_CTX_DAG_OWNER='airflow' AIRFLOW_CTX_DAG_ID='iris_classification' AIRFLOW_CTX_TASK_ID='preprocess_data' AIRFLOW_CTX_EXECUTION_DATE='2024-05-17T10:41:24.581535+00:00' AIRFLOW_CTX_TRY_NUMBER='1' AIRFLOW_CTX_DAG_RUN_ID='manual__2024-05-17T10:41:24.581535+00:00'
[2024-05-17T16:11:32.913+0530] {taskinstance.py:1824} ERROR - Task failed with exception
Traceback (most recent call last):
  File "/Users/aswin/anaconda3/envs/bdl/lib/python3.10/site-packages/airflow/operators/python.py", line 181, in execute
    return_value = self.execute_callable()
  File "/Users/aswin/anaconda3/envs/bdl/lib/python3.10/site-packages/airflow/operators/python.py", line 198, in execute_callable
    return self.python_callable(*self.op_args, **self.op_kwargs)
  File "/Users/aswin/Downloads/Courses/Big Data Lab/Project/dags/iris_prediction.py", line 49, in preprocess_data
    train_data.write.parquet(train_path)
  File "/Users/aswin/anaconda3/envs/bdl/lib/python3.10/site-packages/pyspark/sql/readwriter.py", line 1721, in parquet
    self._jwrite.parquet(path)
  File "/Users/aswin/anaconda3/envs/bdl/lib/python3.10/site-packages/py4j/java_gateway.py", line 1322, in __call__
    return_value = get_return_value(
  File "/Users/aswin/anaconda3/envs/bdl/lib/python3.10/site-packages/pyspark/errors/exceptions/captured.py", line 185, in deco
    raise converted from None
pyspark.errors.exceptions.captured.AnalysisException: [PATH_ALREADY_EXISTS] Path file:/Users/aswin/Downloads/Courses/Big Data Lab/Project/data/train_data_IrisClassification already exists. Set mode as "overwrite" to overwrite the existing path.
[2024-05-17T16:11:32.920+0530] {taskinstance.py:1345} INFO - Marking task as UP_FOR_RETRY. dag_id=iris_classification, task_id=preprocess_data, execution_date=20240517T104124, start_date=20240517T104130, end_date=20240517T104132
[2024-05-17T16:11:32.924+0530] {standard_task_runner.py:104} ERROR - Failed to execute job 8 for task preprocess_data ([PATH_ALREADY_EXISTS] Path file:/Users/aswin/Downloads/Courses/Big Data Lab/Project/data/train_data_IrisClassification already exists. Set mode as "overwrite" to overwrite the existing path.; 31309)
[2024-05-17T16:11:32.935+0530] {local_task_job_runner.py:225} INFO - Task exited with return code 1
[2024-05-17T16:11:32.942+0530] {taskinstance.py:2651} INFO - 0 downstream tasks scheduled from follow-on schedule check
