[2024-05-18T02:53:29.777+0530] {taskinstance.py:1956} INFO - Dependencies all met for dep_context=non-requeueable deps ti=<TaskInstance: iris_classification.preprocess_data manual__2024-05-17T21:23:24.270819+00:00 [queued]>
[2024-05-18T02:53:29.780+0530] {taskinstance.py:1956} INFO - Dependencies all met for dep_context=requeueable deps ti=<TaskInstance: iris_classification.preprocess_data manual__2024-05-17T21:23:24.270819+00:00 [queued]>
[2024-05-18T02:53:29.780+0530] {taskinstance.py:2170} INFO - Starting attempt 1 of 0
[2024-05-18T02:53:29.786+0530] {taskinstance.py:2191} INFO - Executing <Task(PythonOperator): preprocess_data> on 2024-05-17 21:23:24.270819+00:00
[2024-05-18T02:53:29.790+0530] {standard_task_runner.py:60} INFO - Started process 12822 to run task
[2024-05-18T02:53:29.792+0530] {clientserver.py:543} INFO - Closing down clientserver connection
[2024-05-18T02:53:29.796+0530] {standard_task_runner.py:87} INFO - Running: ['airflow', 'tasks', 'run', 'iris_classification', 'preprocess_data', 'manual__2024-05-17T21:23:24.270819+00:00', '--job-id', '69', '--raw', '--subdir', 'DAGS_FOLDER/main.py', '--cfg-path', '/var/folders/fy/4q0txy357vvc35bhsxlfyr8c0000gn/T/tmpez7osnj1']
[2024-05-18T02:53:29.798+0530] {standard_task_runner.py:88} INFO - Job 69: Subtask preprocess_data
[2024-05-18T02:53:29.824+0530] {task_command.py:423} INFO - Running <TaskInstance: iris_classification.preprocess_data manual__2024-05-17T21:23:24.270819+00:00 [running]> on host aswins-macbook-air.local
[2024-05-18T02:53:29.858+0530] {taskinstance.py:2480} INFO - Exporting env vars: AIRFLOW_CTX_DAG_OWNER='airflow' AIRFLOW_CTX_DAG_ID='iris_classification' AIRFLOW_CTX_TASK_ID='preprocess_data' AIRFLOW_CTX_EXECUTION_DATE='2024-05-17T21:23:24.270819+00:00' AIRFLOW_CTX_TRY_NUMBER='1' AIRFLOW_CTX_DAG_RUN_ID='manual__2024-05-17T21:23:24.270819+00:00'
[2024-05-18T02:53:30.591+0530] {clientserver.py:505} INFO - Error while sending or receiving.
Traceback (most recent call last):
  File "/Users/aswin/anaconda3/lib/python3.10/site-packages/py4j/clientserver.py", line 503, in send_command
    self.socket.sendall(command.encode("utf-8"))
BrokenPipeError: [Errno 32] Broken pipe
[2024-05-18T02:53:30.594+0530] {clientserver.py:543} INFO - Closing down clientserver connection
[2024-05-18T02:53:30.594+0530] {java_gateway.py:1052} INFO - Exception while sending command.
Traceback (most recent call last):
  File "/Users/aswin/anaconda3/lib/python3.10/site-packages/py4j/clientserver.py", line 503, in send_command
    self.socket.sendall(command.encode("utf-8"))
BrokenPipeError: [Errno 32] Broken pipe

During handling of the above exception, another exception occurred:

Traceback (most recent call last):
  File "/Users/aswin/anaconda3/lib/python3.10/site-packages/py4j/java_gateway.py", line 1038, in send_command
    response = connection.send_command(command)
  File "/Users/aswin/anaconda3/lib/python3.10/site-packages/py4j/clientserver.py", line 506, in send_command
    raise Py4JNetworkError(
py4j.protocol.Py4JNetworkError: Error while sending
[2024-05-18T02:53:30.596+0530] {clientserver.py:543} INFO - Closing down clientserver connection
[2024-05-18T02:53:35.345+0530] {taskinstance.py:2698} ERROR - Task failed with exception
Traceback (most recent call last):
  File "/Users/aswin/anaconda3/lib/python3.10/site-packages/airflow/models/taskinstance.py", line 433, in _execute_task
    result = execute_callable(context=context, **execute_callable_kwargs)
  File "/Users/aswin/anaconda3/lib/python3.10/site-packages/airflow/operators/python.py", line 199, in execute
    return_value = self.execute_callable()
  File "/Users/aswin/anaconda3/lib/python3.10/site-packages/airflow/operators/python.py", line 216, in execute_callable
    return self.python_callable(*self.op_args, **self.op_kwargs)
  File "/Users/aswin/Downloads/Courses/Big Data Lab/Project/dags/main.py", line 67, in preprocess_data
    train_data.toPandas().to_csv(train_path,index=False)
  File "/Users/aswin/anaconda3/lib/python3.10/site-packages/pandas/util/_decorators.py", line 211, in wrapper
    return func(*args, **kwargs)
  File "/Users/aswin/anaconda3/lib/python3.10/site-packages/pandas/core/generic.py", line 3720, in to_csv
    return DataFrameRenderer(formatter).to_csv(
  File "/Users/aswin/anaconda3/lib/python3.10/site-packages/pandas/util/_decorators.py", line 211, in wrapper
    return func(*args, **kwargs)
  File "/Users/aswin/anaconda3/lib/python3.10/site-packages/pandas/io/formats/format.py", line 1189, in to_csv
    csv_formatter.save()
  File "/Users/aswin/anaconda3/lib/python3.10/site-packages/pandas/io/formats/csvs.py", line 241, in save
    with get_handle(
  File "/Users/aswin/anaconda3/lib/python3.10/site-packages/pandas/io/common.py", line 734, in get_handle
    check_parent_directory(str(handle))
  File "/Users/aswin/anaconda3/lib/python3.10/site-packages/pandas/io/common.py", line 597, in check_parent_directory
    raise OSError(rf"Cannot save file into a non-existent directory: '{parent}'")
OSError: Cannot save file into a non-existent directory: 'data'
[2024-05-18T02:53:35.354+0530] {taskinstance.py:1138} INFO - Marking task as FAILED. dag_id=iris_classification, task_id=preprocess_data, execution_date=20240517T212324, start_date=20240517T212329, end_date=20240517T212335
[2024-05-18T02:53:35.360+0530] {standard_task_runner.py:107} ERROR - Failed to execute job 69 for task preprocess_data (Cannot save file into a non-existent directory: 'data'; 12822)
[2024-05-18T02:53:35.406+0530] {local_task_job_runner.py:234} INFO - Task exited with return code 1
[2024-05-18T02:53:35.415+0530] {taskinstance.py:3280} INFO - 0 downstream tasks scheduled from follow-on schedule check
