[2024-05-18T02:40:11.505+0530] {taskinstance.py:1103} INFO - Dependencies all met for dep_context=non-requeueable deps ti=<TaskInstance: iris_classification.train_model manual__2024-05-17T20:43:39.186070+00:00 [queued]>
[2024-05-18T02:40:11.513+0530] {taskinstance.py:1103} INFO - Dependencies all met for dep_context=requeueable deps ti=<TaskInstance: iris_classification.train_model manual__2024-05-17T20:43:39.186070+00:00 [queued]>
[2024-05-18T02:40:11.514+0530] {taskinstance.py:1308} INFO - Starting attempt 2 of 0
[2024-05-18T02:40:11.541+0530] {taskinstance.py:1327} INFO - Executing <Task(PythonOperator): train_model> on 2024-05-17 20:43:39.186070+00:00
[2024-05-18T02:40:11.546+0530] {standard_task_runner.py:57} INFO - Started process 9693 to run task
[2024-05-18T02:40:11.548+0530] {clientserver.py:543} INFO - Closing down clientserver connection
[2024-05-18T02:40:11.555+0530] {standard_task_runner.py:84} INFO - Running: ['airflow', 'tasks', 'run', 'iris_classification', 'train_model', 'manual__2024-05-17T20:43:39.186070+00:00', '--job-id', '64', '--raw', '--subdir', 'DAGS_FOLDER/main.py', '--cfg-path', '/var/folders/fy/4q0txy357vvc35bhsxlfyr8c0000gn/T/tmp0bgbo8jz']
[2024-05-18T02:40:11.556+0530] {standard_task_runner.py:85} INFO - Job 64: Subtask train_model
[2024-05-18T02:40:11.589+0530] {task_command.py:410} INFO - Running <TaskInstance: iris_classification.train_model manual__2024-05-17T20:43:39.186070+00:00 [running]> on host aswins-macbook-air.local
[2024-05-18T02:40:11.627+0530] {taskinstance.py:1545} INFO - Exporting env vars: AIRFLOW_CTX_DAG_OWNER='airflow' AIRFLOW_CTX_DAG_ID='iris_classification' AIRFLOW_CTX_TASK_ID='train_model' AIRFLOW_CTX_EXECUTION_DATE='2024-05-17T20:43:39.186070+00:00' AIRFLOW_CTX_TRY_NUMBER='2' AIRFLOW_CTX_DAG_RUN_ID='manual__2024-05-17T20:43:39.186070+00:00'
[2024-05-18T02:40:11.633+0530] {taskinstance.py:1824} ERROR - Task failed with exception
Traceback (most recent call last):
  File "/Users/aswin/anaconda3/envs/bdl/lib/python3.10/site-packages/airflow/operators/python.py", line 181, in execute
    return_value = self.execute_callable()
  File "/Users/aswin/anaconda3/envs/bdl/lib/python3.10/site-packages/airflow/operators/python.py", line 198, in execute_callable
    return self.python_callable(*self.op_args, **self.op_kwargs)
  File "/Users/aswin/Downloads/Courses/Big Data Lab/Project/dags/main.py", line 80, in train_model
    train_data = pd.read_csv(train_path)
  File "/Users/aswin/anaconda3/envs/bdl/lib/python3.10/site-packages/pandas/io/parsers/readers.py", line 1026, in read_csv
    return _read(filepath_or_buffer, kwds)
  File "/Users/aswin/anaconda3/envs/bdl/lib/python3.10/site-packages/pandas/io/parsers/readers.py", line 620, in _read
    parser = TextFileReader(filepath_or_buffer, **kwds)
  File "/Users/aswin/anaconda3/envs/bdl/lib/python3.10/site-packages/pandas/io/parsers/readers.py", line 1620, in __init__
    self._engine = self._make_engine(f, self.engine)
  File "/Users/aswin/anaconda3/envs/bdl/lib/python3.10/site-packages/pandas/io/parsers/readers.py", line 1880, in _make_engine
    self.handles = get_handle(
  File "/Users/aswin/anaconda3/envs/bdl/lib/python3.10/site-packages/pandas/io/common.py", line 873, in get_handle
    handle = open(
FileNotFoundError: [Errno 2] No such file or directory: 'data/train_data_IrisClassification'
[2024-05-18T02:40:11.637+0530] {taskinstance.py:1345} INFO - Marking task as FAILED. dag_id=iris_classification, task_id=train_model, execution_date=20240517T204339, start_date=20240517T211011, end_date=20240517T211011
[2024-05-18T02:40:11.642+0530] {standard_task_runner.py:104} ERROR - Failed to execute job 64 for task train_model ([Errno 2] No such file or directory: 'data/train_data_IrisClassification'; 9693)
[2024-05-18T02:40:11.657+0530] {local_task_job_runner.py:225} INFO - Task exited with return code 1
[2024-05-18T02:40:11.663+0530] {taskinstance.py:2651} INFO - 0 downstream tasks scheduled from follow-on schedule check
