[2024-05-18T11:43:02.757+0530] {taskinstance.py:1956} INFO - Dependencies all met for dep_context=non-requeueable deps ti=<TaskInstance: iris_classification.preprocess_data manual__2024-05-18T06:12:54.555257+00:00 [queued]>
[2024-05-18T11:43:02.764+0530] {taskinstance.py:1956} INFO - Dependencies all met for dep_context=requeueable deps ti=<TaskInstance: iris_classification.preprocess_data manual__2024-05-18T06:12:54.555257+00:00 [queued]>
[2024-05-18T11:43:02.764+0530] {taskinstance.py:2170} INFO - Starting attempt 1 of 0
[2024-05-18T11:43:02.773+0530] {taskinstance.py:2191} INFO - Executing <Task(PythonOperator): preprocess_data> on 2024-05-18 06:12:54.555257+00:00
[2024-05-18T11:43:02.778+0530] {standard_task_runner.py:60} INFO - Started process 34005 to run task
[2024-05-18T11:43:02.780+0530] {clientserver.py:543} INFO - Closing down clientserver connection
[2024-05-18T11:43:02.787+0530] {standard_task_runner.py:87} INFO - Running: ['airflow', 'tasks', 'run', 'iris_classification', 'preprocess_data', 'manual__2024-05-18T06:12:54.555257+00:00', '--job-id', '105', '--raw', '--subdir', 'DAGS_FOLDER/main.py', '--cfg-path', '/var/folders/fy/4q0txy357vvc35bhsxlfyr8c0000gn/T/tmp65vtp4rc']
[2024-05-18T11:43:02.789+0530] {standard_task_runner.py:88} INFO - Job 105: Subtask preprocess_data
[2024-05-18T11:43:02.831+0530] {task_command.py:423} INFO - Running <TaskInstance: iris_classification.preprocess_data manual__2024-05-18T06:12:54.555257+00:00 [running]> on host aswins-macbook-air.local
[2024-05-18T11:43:02.883+0530] {taskinstance.py:2480} INFO - Exporting env vars: AIRFLOW_CTX_DAG_OWNER='airflow' AIRFLOW_CTX_DAG_ID='iris_classification' AIRFLOW_CTX_TASK_ID='preprocess_data' AIRFLOW_CTX_EXECUTION_DATE='2024-05-18T06:12:54.555257+00:00' AIRFLOW_CTX_TRY_NUMBER='1' AIRFLOW_CTX_DAG_RUN_ID='manual__2024-05-18T06:12:54.555257+00:00'
[2024-05-18T11:43:03.118+0530] {clientserver.py:505} INFO - Error while sending or receiving.
Traceback (most recent call last):
  File "/Users/aswin/anaconda3/lib/python3.10/site-packages/py4j/clientserver.py", line 503, in send_command
    self.socket.sendall(command.encode("utf-8"))
BrokenPipeError: [Errno 32] Broken pipe
[2024-05-18T11:43:03.120+0530] {clientserver.py:543} INFO - Closing down clientserver connection
[2024-05-18T11:43:03.121+0530] {java_gateway.py:1052} INFO - Exception while sending command.
Traceback (most recent call last):
  File "/Users/aswin/anaconda3/lib/python3.10/site-packages/py4j/clientserver.py", line 503, in send_command
    self.socket.sendall(command.encode("utf-8"))
BrokenPipeError: [Errno 32] Broken pipe

During handling of the above exception, another exception occurred:

Traceback (most recent call last):
  File "/Users/aswin/anaconda3/lib/python3.10/site-packages/py4j/java_gateway.py", line 1038, in send_command
    response = connection.send_command(command)
  File "/Users/aswin/anaconda3/lib/python3.10/site-packages/py4j/clientserver.py", line 506, in send_command
    raise Py4JNetworkError(
py4j.protocol.Py4JNetworkError: Error while sending
[2024-05-18T11:43:03.123+0530] {clientserver.py:543} INFO - Closing down clientserver connection
